Workbook

Sheet README
B2: Red Team Time-to-Detection (TTD) Metrics
B4: Definition | C4: Time-to-Detection measures the gap between when a red team event should trigger an alert and when the alert is actually surfaced to incident responders. Goal: minimize the window in which activity goes unnoticed or undetected.
B5: Why it matters | C5: Validates that "water is flowing through the pipes" and alerting works as intended. Gaps are worked with detection engineering to add/update rules and close telemetry or tooling gaps.
B6: One log drives everything | C6: There is a single sheet — Activity & Event Log — where you record every red team action. It replaces the old separate activity tracker. One row per action. A row feeds the Dashboard only when its Severity (col G) is filled, which marks it a measured detection/containment event; actions you log for deconfliction but don't measure (just leave Severity blank) stay as log entries and don't affect the metrics. The Dashboard reads only from this sheet.
B7: Clock start / stop | C7: Start = Activity & Event Log column I (action executed). Stop = column L (actionable alert surfaced to incident responders).
B8: Pipeline stages | C8: TTD is split into three stages to show where time is lost: 1) Telemetry Latency = Telemetry Logged − Executed 2) Alert Generation Latency = Alert Generated − Telemetry Logged 3) Triage Latency = Alert Surfaced − Alert Generated
B9: Auto-classification | C9: Each event is classified in column V: • Telemetry Blind Spot — no telemetry, alert, or surfaced timestamp • Missed Alert — telemetry exists but no alert generated/surfaced • Triage Delay — alert generated but never surfaced, or TTD missed SLA and triage latency > severity's triage threshold • Detected - SLA Breach — surfaced, TTD > SLA target, delay was upstream of triage • Detected - Within SLA — surfaced within SLA target
B10: — Time-to-Containment — | C10: Measures how long it takes to stop the adversary from taking further action after an alert. Clock starts when the alert is surfaced to IR (Event Log col L) and stops when C2 is blocked and the attacker can no longer act (col Z). Unlike detection, this shows when the adversary is actually prevented from progressing — resilient C2 can survive initial isolation, so containment is not complete until C2 is disrupted.
B11: Containment stages | C11: 1) Response Initiation = Containment Started − Alert Surfaced (workflow efficiency) 2) Host Isolation Latency = Host Isolated − Containment Started 3) C2 Disruption Latency = C2 Blocked − Host Isolated
B12: Containment results | C12: Column AI classifies each surfaced event, mapping to the three gap areas: • No Containment Action — responders never acted (workflow gap) • Host Isolation Gap — action started but host never isolated • C2 Persisted — host isolated but C2 never blocked (the resilient-C2 gap) • Contained - SLA Breach / Within SLA — C2 blocked, over / under the containment SLA • N/A - Not Detected — event never surfaced, so containment can't be measured
B13: Log layout | C13: Columns on the Activity & Event Log, left to right: • A–H: identity — ID, engagement, tactic, technique, description, target, Severity, expected detection source • I–L: detection timestamps (executed, telemetry, alert generated, alert surfaced) • P–W: detection calculations • X–Z: containment timestamps (action started, host isolated, C2 blocked) • AC–AJ: containment calculations • AK–AU: operator & deconfliction — operator, source host, command/procedure, tool/C2, worked?, result, deconfliction status, reported-by, cleanup status/notes, comments
B14: How to use | C14: 1) Set TTD + containment SLA targets, triage thresholds and engagement names on Settings. 2) Log one row per action on the Activity & Event Log (blue = inputs; grey = formulas). 3) For a measured event, fill Severity and the relevant timestamps; leave a timestamp blank if that stage never happened — blanks drive gap classification. 4) Review the Dashboard; it recalculates automatically. Formulas cover 500 rows.
B15: Timestamps | C15: Enter as date + time, e.g. 2026-09-14 10:32 (24-hour). All latencies are in minutes.
... B17: Color legend | C17: Blue text = input · Grey fill = calculated, do not edit · Yellow = key assumption. Header bands: navy = identity/detection, green = containment, purple = operator & deconfliction.

Sheet Dashboard
B1: Detection & Containment Dashboard
B2: All values calculate from the Event Log. Latencies in minutes. Left band = Time-to-Detection, right band = Time-to-Containment. | I2: TIME-TO-CONTAINMENT
B3: Headline KPI | C3: Value | E3: Detection Result | F3: Count | G3: % of Events | I3: Containment Result | J3: Count | K3: % of Events
B4: Total Measured Events | C4: =COUNTIF('Activity & Event Log'!$G$5:$G$504,"?*") -> 16 | E4: Detected - Within SLA | F4: =COUNTIF('Activity & Event Log'!$V$5:$V$504,E4) -> 9 | G4: =IFERROR(F4/$C$4,0) -> 0.5625 | I4: Contained - Within SLA | J4: =COUNTIF('Activity & Event Log'!$AI$5:$AI$504,I4) -> 9 | K4: =IFERROR(J4/$C$4,"") -> 0.5625
B5: Alerts Surfaced to IR | C5: =SUM('Activity & Event Log'!$W$5:$W$504) -> 12 | E5: Detected - SLA Breach | F5: =COUNTIF('Activity & Event Log'!$V$5:$V$504,E5) -> 0 | G5: =IFERROR(F5/$C$4,0) -> 0 | I5: Contained - SLA Breach | J5: =COUNTIF('Activity & Event Log'!$AI$5:$AI$504,I5) -> 0 | K5: =IFERROR(J5/$C$4,"") -> 0
B6: Detection Rate | C6: =IFERROR(C5/C4,0) -> 0.75 | E6: Triage Delay | F6: =COUNTIF('Activity & Event Log'!$V$5:$V$504,E6) -> 3 | G6: =IFERROR(F6/$C$4,0) -> 0.1875 | I6: C2 Persisted | J6: =COUNTIF('Activity & Event Log'!$AI$5:$AI$504,I6) -> 2 | K6: =IFERROR(J6/$C$4,"") -> 0.125
B7: % Within TTD SLA | C7: =IFERROR(COUNTIF('Activity & Event Log'!$U$5:$U$504,"Yes")/C4,0) -> 0.5625 | E7: Missed Alert | F7: =COUNTIF('Activity & Event Log'!$V$5:$V$504,E7) -> 2 | G7: =IFERROR(F7/$C$4,0) -> 0.125 | I7: Host Isolation Gap | J7: =COUNTIF('Activity & Event Log'!$AI$5:$AI$504,I7) -> 1 | K7: =IFERROR(J7/$C$4,"") -> 0.0625
B8: Mean TTD (min) | C8: =IFERROR(AVERAGE('Activity & Event Log'!$S$5:$S$504),0) -> 43.666667 | E8: Telemetry Blind Spot | F8: =COUNTIF('Activity & Event Log'!$V$5:$V$504,E8) -> 2 | G8: =IFERROR(F8/$C$4,0) -> 0.125 | I8: No Containment Action | J8: =COUNTIF('Activity & Event Log'!$AI$5:$AI$504,I8) -> 0 | K8: =IFERROR(J8/$C$4,"") -> 0
B9: Median TTD (min) | C9: =IFERROR(MEDIAN('Activity & Event Log'!$S$5:$S$504),0) -> 31.5 | I9: N/A - Not Detected | J9: =COUNTIF('Activity & Event Log'!$AI$5:$AI$504,I9) -> 4 | K9: =IFERROR(J9/$C$4,"") -> 0.25
B10: 90th Percentile TTD (min) | C10: =IFERROR(PERCENTILE('Activity & Event Log'!$S$5:$S$504,0.9),0) -> 92.5 | E10: Detection Pipeline Stage | F10: Avg (min) | G10: Max (min)
B11: Max TTD (min) | C11: =IFERROR(MAX('Activity & Event Log'!$S$5:$S$504),0) -> 140 | E11: Telemetry Latency | F11: =IFERROR(AVERAGE('Activity & Event Log'!$P$5:$P$504),0) -> 1.7142857 | G11: =IFERROR(MAX('Activity & Event Log'!$P$5:$P$504),0) -> 5 | I11: Containment Pipeline Stage | J11: Avg (min) | K11: Max (min)
B12: Open Detection Gaps | C12: =COUNTIFS('Activity & Event Log'!$N$5:$N$504,"Open")+COUNTIFS('Activity & Event Log'!$N$5:$N$504,"In Progress") -> 1 | E12: Alert Generation Latency | F12: =IFERROR(AVERAGE('Activity & Event Log'!$Q$5:$Q$504),0) -> 3.375 | G12: =IFERROR(MAX('Activity & Event Log'!$Q$5:$Q$504),0) -> 11 | I12: Response Initiation Latency | J12: =IFERROR(AVERAGE('Activity & Event Log'!$AC$5:$AC$504),0) -> 10.416667 | K12: =IFERROR(MAX('Activity & Event Log'!$AC$5:$AC$504),0) -> 40
E13: Triage Latency | F13: =IFERROR(AVERAGE('Activity & Event Log'!$R$5:$R$504),0) -> 38.791667 | G13: =IFERROR(MAX('Activity & Event Log'!$R$5:$R$504),0) -> 129 | I13: Host Isolation Latency | J13: =IFERROR(AVERAGE('Activity & Event Log'!$AD$5:$AD$504),0) -> 16.454545 | K13: =IFERROR(MAX('Activity & Event Log'!$AD$5:$AD$504),0) -> 45
B14: Headline KPI | C14: Value | E14: Total Time-to-Detection | F14: =IFERROR(AVERAGE('Activity & Event Log'!$S$5:$S$504),0) -> 43.666667 | G14: =IFERROR(MAX('Activity & Event Log'!$S$5:$S$504),0) -> 140 | I14: C2 Disruption Latency | J14: =IFERROR(AVERAGE('Activity & Event Log'!$AE$5:$AE$504),0) -> 27.444444 | K14: =IFERROR(MAX('Activity & Event Log'!$AE$5:$AE$504),0) -> 70
B15: Eligible Events (Surfaced) | C15: =SUM('Activity & Event Log'!$W$5:$W$504) -> 12 | I15: Total Time-to-Containment | J15: =IFERROR(AVERAGE('Activity & Event Log'!$AF$5:$AF$504),0) -> 47 | K15: =IFERROR(MAX('Activity & Event Log'!$AF$5:$AF$504),0) -> 120
B16: Contained (C2 Blocked) | C16: =SUM('Activity & Event Log'!$AJ$5:$AJ$504) -> 9
B17: Containment Rate | C17: =IFERROR(C16/C15,0) -> 0.75
B18: % Within Containment SLA | C18: =IFERROR(COUNTIF('Activity & Event Log'!$AH$5:$AH$504,"Yes")/MAX(C15,1),0) -> 0.75
B19: Mean TTC (min) | C19: =IFERROR(AVERAGE('Activity & Event Log'!$AF$5:$AF$504),0) -> 47
B20: Median TTC (min) | C20: =IFERROR(MEDIAN('Activity & Event Log'!$AF$5:$AF$504),0) -> 30
B21: 90th Percentile TTC (min) | C21: =IFERROR(PERCENTILE('Activity & Event Log'!$AF$5:$AF$504,0.9),0) -> 96
B22: Max TTC (min) | C22: =IFERROR(MAX('Activity & Event Log'!$AF$5:$AF$504),0) -> 120
B23: C2 Persisted (open gap) | C23: =COUNTIF('Activity & Event Log'!$AI$5:$AI$504,"C2 Persisted") -> 2
B25: By MITRE ATT&CK Tactic
B26: Tactic | C26: Events | D26: Surfaced | E26: Detection Rate | F26: Mean TTD (min) | G26: Max TTD (min) | H26: % Within SLA | I26: Missed Alerts | J26: Blind Spots | K26: Triage Delays
B27: Reconnaissance | C27: =COUNTIFS('Activity & Event Log'!$C$5:$C$504,$B27,'Activity & Event Log'!$G$5:$G$504,"?*") -> 0 | D27: =SUMIFS('Activity & Event Log'!$W$5:$W$504,'Activity & Event Log'!$C$5:$C$504,$B27) -> 0 | E27: =IFERROR(D27/C27,"") | F27: =IFERROR(AVERAGEIFS('Activity & Event Log'!$S$5:$S$504,'Activity & Event Log'!$C$5:$C$504,$B27),"") | G27: =IF(D27=0,"",_xlfn.MAXIFS('Activity & Event Log'!$S$5:$S$504,'Activity & Event Log'!$C$5:$C$504,$B27)) | H27: =IFERROR(COUNTIFS('Activity & Event Log'!$C$5:$C$504,$B27,'Activity & Event Log'!$U$5:$U$504,"Yes")/C27,"") | I27: =COUNTIFS('Activity & Event Log'!$C$5:$C$504,$B27,'Activity & Event Log'!$V$5:$V$504,"Missed Alert") -> 0 | J27: =COUNTIFS('Activity & Event Log'!$C$5:$C$504,$B27,'Activity & Event Log'!$V$5:$V$504,"Telemetry Blind Spot") -> 0 | K27: =COUNTIFS('Activity & Event Log'!$C$5:$C$504,$B27,'Activity & Event Log'!$V$5:$V$504,"Triage Delay") -> 0
B28: Resource Development | C28: =COUNTIFS('Activity & Event Log'!$C$5:$C$504,$B28,'Activity & Event Log'!$G$5:$G$504,"?*") -> 0 | D28: =SUMIFS('Activity & Event Log'!$W$5:$W$504,'Activity & Event Log'!$C$5:$C$504,$B28) -> 0 | E28: =IFERROR(D28/C28,"") | F28: =IFERROR(AVERAGEIFS('Activity & Event Log'!$S$5:$S$504,'Activity & Event Log'!$C$5:$C$504,$B28),"") | G28: =IF(D28=0,"",_xlfn.MAXIFS('Activity & Event Log'!$S$5:$S$504,'Activity & Event Log'!$C$5:$C$504,$B28)) | H28: =IFERROR(COUNTIFS('Activity & Event Log'!$C$5:$C$504,$B28,'Activity & Event Log'!$U$5:$U$504,"Yes")/C28,"") | I28: =COUNTIFS('Activity & Event Log'!$C$5:$C$504,$B28,'Activity & Event Log'!$V$5:$V$504,"Missed Alert") -> 0 | J28: =COUNTIFS('Activity & Event Log'!$C$5:$C$504,$B28,'Activity & Event Log'!$V$5:$V$504,"Telemetry Blind Spot") -> 0 | K28: =COUNTIFS('Activity & Event Log'!$C$5:$C$504,$B28,'Activity & Event Log'!$V$5:$V$504,"Triage Delay") -> 0
B29: Initial Access | C29: =COUNTIFS('Activity & Event Log'!$C$5:$C$504,$B29,'Activity & Event Log'!$G$5:$G$504,"?*") -> 2 | D29: =SUMIFS('Activity & Event Log'!$W$5:$W$504,'Activity & Event Log'!$C$5:$C$504,$B29) -> 2 | E29: =IFERROR(D29/C29,"") -> 1 | F29: =IFERROR(AVERAGEIFS('Activity & Event Log'!$S$5:$S$504,'Activity & Event Log'!$C$5:$C$504,$B29),"") -> 36.5 | G29: =IF(D29=0,"",_xlfn.MAXIFS('Activity & Event Log'!$S$5:$S$504,'Activity & Event Log'!$C$5:$C$504,$B29)) -> 52 | H29: =IFERROR(COUNTIFS('Activity & Event Log'!$C$5:$C$504,$B29,'Activity & Event Log'!$U$5:$U$504,"Yes")/C29,"") -> 1 | I29: =COUNTIFS('Activity & Event Log'!$C$5:$C$504,$B29,'Activity & Event Log'!$V$5:$V$504,"Missed Alert") -> 0 | J29: =COUNTIFS('Activity & Event Log'!$C$5:$C$504,$B29,'Activity & Event Log'!$V$5:$V$504,"Telemetry Blind Spot") -> 0 | K29: =COUNTIFS('Activity & Event Log'!$C$5:$C$504,$B29,'Activity & Event Log'!$V$5:$V$504,"Triage Delay") -> 0
B30: Execution | C30: =COUNTIFS('Activity & Event Log'!$C$5:$C$504,$B30,'Activity & Event Log'!$G$5:$G$504,"?*") -> 2 | D30: =SUMIFS('Activity & Event Log'!$W$5:$W$504,'Activity & Event Log'!$C$5:$C$504,$B30) -> 2 | E30: =IFERROR(D30/C30,"") -> 1 | F30: =IFERROR(AVERAGEIFS('Activity & Event Log'!$S$5:$S$504,'Activity & Event Log'!$C$5:$C$504,$B30),"") -> 22.5 | G30: =IF(D30=0,"",_xlfn.MAXIFS('Activity & Event Log'!$S$5:$S$504,'Activity & Event Log'!$C$5:$C$504,$B30)) -> 38 | H30: =IFERROR(COUNTIFS('Activity & Event Log'!$C$5:$C$504,$B30,'Activity & Event Log'!$U$5:$U$504,"Yes")/C30,"") -> 0.5 | I30: =COUNTIFS('Activity & Event Log'!$C$5:$C$504,$B30,'Activity & Event Log'!$V$5:$V$504,"Missed Alert") -> 0 | J30: =COUNTIFS('Activity & Event Log'!$C$5:$C$504,$B30,'Activity & Event Log'!$V$5:$V$504,"Telemetry Blind Spot") -> 0 | K30: =COUNTIFS('Activity & Event Log'!$C$5:$C$504,$B30,'Activity & Event Log'!$V$5:$V$504,"Triage Delay") -> 1
B31: Persistence | C31: =COUNTIFS('Activity & Event Log'!$C$5:$C$504,$B31,'Activity & Event Log'!$G$5:$G$504,"?*") -> 2 | D31: =SUMIFS('Activity & Event Log'!$W$5:$W$504,'Activity & Event Log'!$C$5:$C$504,$B31) -> 1 | E31: =IFERROR(D31/C31,"") -> 0.5 | F31: =IFERROR(AVERAGEIFS('Activity & Event Log'!$S$5:$S$504,'Activity & Event Log'!$C$5:$C$504,$B31),"") -> 25 | G31: =IF(D31=0,"",_xlfn.MAXIFS('Activity & Event Log'!$S$5:$S$504,'Activity & Event Log'!$C$5:$C$504,$B31)) -> 25 | H31: =IFERROR(COUNTIFS('Activity & Event Log'!$C$5:$C$504,$B31,'Activity & Event Log'!$U$5:$U$504,"Yes")/C31,"") -> 0.5 | I31: =COUNTIFS('Activity & Event Log'!$C$5:$C$504,$B31,'Activity & Event Log'!$V$5:$V$504,"Missed Alert") -> 1 | J31: =COUNTIFS('Activity & Event Log'!$C$5:$C$504,$B31,'Activity & Event Log'!$V$5:$V$504,"Telemetry Blind Spot") -> 0 | K31: =COUNTIFS('Activity & Event Log'!$C$5:$C$504,$B31,'Activity & Event Log'!$V$5:$V$504,"Triage Delay") -> 0
B32: Privilege Escalation | C32: =COUNTIFS('Activity & Event Log'!$C$5:$C$504,$B32,'Activity & Event Log'!$G$5:$G$504,"?*") -> 0 | D32: =SUMIFS('Activity & Event Log'!$W$5:$W$504,'Activity & Event Log'!$C$5:$C$504,$B32) -> 0 | E32: =IFERROR(D32/C32,"") | F32: =IFERROR(AVERAGEIFS('Activity & Event Log'!$S$5:$S$504,'Activity & Event Log'!$C$5:$C$504,$B32),"") | G32: =IF(D32=0,"",_xlfn.MAXIFS('Activity & Event Log'!$S$5:$S$504,'Activity & Event Log'!$C$5:$C$504,$B32)) | H32: =IFERROR(COUNTIFS('Activity & Event Log'!$C$5:$C$504,$B32,'Activity & Event Log'!$U$5:$U$504,"Yes")/C32,"") | I32: =COUNTIFS('Activity & Event Log'!$C$5:$C$504,$B32,'Activity & Event Log'!$V$5:$V$504,"Missed Alert") -> 0 | J32: =COUNTIFS('Activity & Event Log'!$C$5:$C$504,$B32,'Activity & Event Log'!$V$5:$V$504,"Telemetry Blind Spot") -> 0 | K32: =COUNTIFS('Activity & Event Log'!$C$5:$C$504,$B32,'Activity & Event Log'!$V$5:$V$504,"Triage Delay") -> 0
B33: Defense Evasion | C33: =COUNTIFS('Activity & Event Log'!$C$5:$C$504,$B33,'Activity & Event Log'!$G$5:$G$504,"?*") -> 2 | D33: =SUMIFS('Activity & Event Log'!$W$5:$W$504,'Activity & Event Log'!$C$5:$C$504,$B33) -> 2 | E33: =IFERROR(D33/C33,"") -> 1 | F33: =IFERROR(AVERAGEIFS('Activity & Event Log'!$S$5:$S$504,'Activity & Event Log'!$C$5:$C$504,$B33),"") -> 7.5 | G33: =IF(D33=0,"",_xlfn.MAXIFS('Activity & Event Log'!$S$5:$S$504,'Activity & Event Log'!$C$5:$C$504,$B33)) -> 9 | H33: =IFERROR(COUNTIFS('Activity & Event Log'!$C$5:$C$504,$B33,'Activity & Event Log'!$U$5:$U$504,"Yes")/C33,"") -> 1 | I33: =COUNTIFS('Activity & Event Log'!$C$5:$C$504,$B33,'Activity & Event Log'!$V$5:$V$504,"Missed Alert") -> 0 | J33: =COUNTIFS('Activity & Event Log'!$C$5:$C$504,$B33,'Activity & Event Log'!$V$5:$V$504,"Telemetry Blind Spot") -> 0 | K33: =COUNTIFS('Activity & Event Log'!$C$5:$C$504,$B33,'Activity & Event Log'!$V$5:$V$504,"Triage Delay") -> 0
B34: Credential Access | C34: =COUNTIFS('Activity & Event Log'!$C$5:$C$504,$B34,'Activity & Event Log'!$G$5:$G$504,"?*") -> 2 | D34: =SUMIFS('Activity & Event Log'!$W$5:$W$504,'Activity & Event Log'!$C$5:$C$504,$B34) -> 2 | E34: =IFERROR(D34/C34,"") -> 1 | F34: =IFERROR(AVERAGEIFS('Activity & Event Log'!$S$5:$S$504,'Activity & Event Log'!$C$5:$C$504,$B34),"") -> 54 | G34: =IF(D34=0,"",_xlfn.MAXIFS('Activity & Event Log'!$S$5:$S$504,'Activity & Event Log'!$C$5:$C$504,$B34)) -> 95 | H34: =IFERROR(COUNTIFS('Activity & Event Log'!$C$5:$C$504,$B34,'Activity & Event Log'!$U$5:$U$504,"Yes")/C34,"") -> 0.5 | I34: =COUNTIFS('Activity & Event Log'!$C$5:$C$504,$B34,'Activity & Event Log'!$V$5:$V$504,"Missed Alert") -> 0 | J34: =COUNTIFS('Activity & Event Log'!$C$5:$C$504,$B34,'Activity & Event Log'!$V$5:$V$504,"Telemetry Blind Spot") -> 0 | K34: =COUNTIFS('Activity & Event Log'!$C$5:$C$504,$B34,'Activity & Event Log'!$V$5:$V$504,"Triage Delay") -> 1
B35: Discovery | C35: =COUNTIFS('Activity & Event Log'!$C$5:$C$504,$B35,'Activity & Event Log'!$G$5:$G$504,"?*") -> 2 | D35: =SUMIFS('Activity & Event Log'!$W$5:$W$504,'Activity & Event Log'!$C$5:$C$504,$B35) -> 1 | E35: =IFERROR(D35/C35,"") -> 0.5 | F35: =IFERROR(AVERAGEIFS('Activity & Event Log'!$S$5:$S$504,'Activity & Event Log'!$C$5:$C$504,$B35),"") -> 70 | G35: =IF(D35=0,"",_xlfn.MAXIFS('Activity & Event Log'!$S$5:$S$504,'Activity & Event Log'!$C$5:$C$504,$B35)) -> 70 | H35: =IFERROR(COUNTIFS('Activity & Event Log'!$C$5:$C$504,$B35,'Activity & Event Log'!$U$5:$U$504,"Yes")/C35,"") -> 0.5 | I35: =COUNTIFS('Activity & Event Log'!$C$5:$C$504,$B35,'Activity & Event Log'!$V$5:$V$504,"Missed Alert") -> 0 | J35: =COUNTIFS('Activity & Event Log'!$C$5:$C$504,$B35,'Activity & Event Log'!$V$5:$V$504,"Telemetry Blind Spot") -> 1 | K35: =COUNTIFS('Activity & Event Log'!$C$5:$C$504,$B35,'Activity & Event Log'!$V$5:$V$504,"Triage Delay") -> 0
B36: Lateral Movement | C36: =COUNTIFS('Activity & Event Log'!$C$5:$C$504,$B36,'Activity & Event Log'!$G$5:$G$504,"?*") -> 2 | D36: =SUMIFS('Activity & Event Log'!$W$5:$W$504,'Activity & Event Log'!$C$5:$C$504,$B36) -> 2 | E36: =IFERROR(D36/C36,"") -> 1 | F36: =IFERROR(AVERAGEIFS('Activity & Event Log'!$S$5:$S$504,'Activity & Event Log'!$C$5:$C$504,$B36),"") -> 94 | G36: =IF(D36=0,"",_xlfn.MAXIFS('Activity & Event Log'!$S$5:$S$504,'Activity & Event Log'!$C$5:$C$504,$B36)) -> 140 | H36: =IFERROR(COUNTIFS('Activity & Event Log'!$C$5:$C$504,$B36,'Activity & Event Log'!$U$5:$U$504,"Yes")/C36,"") -> 0.5 | I36: =COUNTIFS('Activity & Event Log'!$C$5:$C$504,$B36,'Activity & Event Log'!$V$5:$V$504,"Missed Alert") -> 0 | J36: =COUNTIFS('Activity & Event Log'!$C$5:$C$504,$B36,'Activity & Event Log'!$V$5:$V$504,"Telemetry Blind Spot") -> 0 | K36: =COUNTIFS('Activity & Event Log'!$C$5:$C$504,$B36,'Activity & Event Log'!$V$5:$V$504,"Triage Delay") -> 1
B37: Collection | C37: =COUNTIFS('Activity & Event Log'!$C$5:$C$504,$B37,'Activity & Event Log'!$G$5:$G$504,"?*") -> 0 | D37: =SUMIFS('Activity & Event Log'!$W$5:$W$504,'Activity & Event Log'!$C$5:$C$504,$B37) -> 0 | E37: =IFERROR(D37/C37,"") | F37: =IFERROR(AVERAGEIFS('Activity & Event Log'!$S$5:$S$504,'Activity & Event Log'!$C$5:$C$504,$B37),"") | G37: =IF(D37=0,"",_xlfn.MAXIFS('Activity & Event Log'!$S$5:$S$504,'Activity & Event Log'!$C$5:$C$504,$B37)) | H37: =IFERROR(COUNTIFS('Activity & Event Log'!$C$5:$C$504,$B37,'Activity & Event Log'!$U$5:$U$504,"Yes")/C37,"") | I37: =COUNTIFS('Activity & Event Log'!$C$5:$C$504,$B37,'Activity & Event Log'!$V$5:$V$504,"Missed Alert") -> 0 | J37: =COUNTIFS('Activity & Event Log'!$C$5:$C$504,$B37,'Activity & Event Log'!$V$5:$V$504,"Telemetry Blind Spot") -> 0 | K37: =COUNTIFS('Activity & Event Log'!$C$5:$C$504,$B37,'Activity & Event Log'!$V$5:$V$504,"Triage Delay") -> 0
B38: Command and Control | C38: =COUNTIFS('Activity & Event Log'!$C$5:$C$504,$B38,'Activity & Event Log'!$G$5:$G$504,"?*") -> 2 | D38: =SUMIFS('Activity & Event Log'!$W$5:$W$504,'Activity & Event Log'!$C$5:$C$504,$B38) -> 0 | E38: =IFERROR(D38/C38,"") -> 0 | F38: =IFERROR(AVERAGEIFS('Activity & Event Log'!$S$5:$S$504,'Activity & Event Log'!$C$5:$C$504,$B38),"") | G38: =IF(D38=0,"",_xlfn.MAXIFS('Activity & Event Log'!$S$5:$S$504,'Activity & Event Log'!$C$5:$C$504,$B38)) | H38: =IFERROR(COUNTIFS('Activity & Event Log'!$C$5:$C$504,$B38,'Activity & Event Log'!$U$5:$U$504,"Yes")/C38,"") -> 0 | I38: =COUNTIFS('Activity & Event Log'!$C$5:$C$504,$B38,'Activity & Event Log'!$V$5:$V$504,"Missed Alert") -> 1 | J38: =COUNTIFS('Activity & Event Log'!$C$5:$C$504,$B38,'Activity & Event Log'!$V$5:$V$504,"Telemetry Blind Spot") -> 1 | K38: =COUNTIFS('Activity & Event Log'!$C$5:$C$504,$B38,'Activity & Event Log'!$V$5:$V$504,"Triage Delay") -> 0
... B40: Impact | C40: =COUNTIFS('Activity & Event Log'!$C$5:$C$504,$B40,'Activity & Event Log'!$G$5:$G$504,"?*") -> 0 | D40: =SUMIFS('Activity & Event Log'!$W$5:$W$504,'Activity & Event Log'!$C$5:$C$504,$B40) -> 0 | E40: =IFERROR(D40/C40,"") | F40: =IFERROR(AVERAGEIFS('Activity & Event Log'!$S$5:$S$504,'Activity & Event Log'!$C$5:$C$504,$B40),"") | G40: =IF(D40=0,"",_xlfn.MAXIFS('Activity & Event Log'!$S$5:$S$504,'Activity & Event Log'!$C$5:$C$504,$B40)) | H40: =IFERROR(COUNTIFS('Activity & Event Log'!$C$5:$C$504,$B40,'Activity & Event Log'!$U$5:$U$504,"Yes")/C40,"") | I40: =COUNTIFS('Activity & Event Log'!$C$5:$C$504,$B40,'Activity & Event Log'!$V$5:$V$504,"Missed Alert") -> 0 | J40: =COUNTIFS('Activity & Event Log'!$C$5:$C$504,$B40,'Activity & Event Log'!$V$5:$V$504,"Telemetry Blind Spot") -> 0 | K40: =COUNTIFS('Activity & Event Log'!$C$5:$C$504,$B40,'Activity & Event Log'!$V$5:$V$504,"Triage Delay") -> 0
B42: By Severity
B43: Severity | C43: Events | D43: Surfaced | E43: Detection Rate | F43: Mean TTD (min) | G43: Max TTD (min) | H43: % Within SLA | I43: Missed Alerts | J43: Blind Spots | K43: Triage Delays
...

Sheet Settings
A1: Settings & Lists
A2: Yellow cells are assumptions — set to your SOC's targets (defaults are placeholders, not an industry standard).
O3: Technique list — enter the ATT&CK techniques in scope (up to 100 rows). Keep grouped by tactic. | S3: Engagement details for deconfliction
A4: Severity | B4: TTD SLA Target (min) | C4: Triage Threshold (min) | D4: Containment SLA Target (min) | E4: MITRE ATT&CK Tactic | F4: Detection Source | G4: Remediation Status | H4: Engagements (edit) | J4: Activity Outcome | K4: Detected? | L4: Deconfliction Status | M4: Cleanup Status | O4: Technique ID | P4: Technique Name | Q4: Parent Tactic | S4: Engagement | T4: Start Date | U4: End Date | V4: Trusted Agent / White Cell | W4: Deconfliction Contact | X4: Authorization / ROE Ref | Y4: Time Zone Used
A5: Critical | B5: 15 | C5: 5 | D5: 60 | E5: Reconnaissance | F5: EDR | G5: Not Required | H5: Q2-2026 Engagement | J5: Success | K5: Yes | L5: Not Required | M5: Not Required | O5: T1566.001 | P5: Spearphishing Attachment | Q5: Initial Access | S5: =IF(H5="","",H5) -> Q2-2026 Engagement | Y5: UTC
A6: High | B6: 60 | C6: 15 | D6: 240 | E6: Resource Development | F6: SIEM | G6: Open | H6: Q3-2026 Engagement | J6: Partial | K6: No | L6: Pending | M6: Pending | O6: T1059.001 | P6: PowerShell | Q6: Execution | S6: =IF(H6="","",H6) -> Q3-2026 Engagement | Y6: UTC
A7: Medium | B7: 240 | C7: 60 | D7: 1440 | E7: Initial Access | F7: NDR | G7: In Progress | J7: Failed | K7: Unknown | L7: Confirmed Red Team | M7: Complete | O7: T1053.005 | P7: Scheduled Task | Q7: Persistence | S7: =IF(H7="","",H7)
A8: Low | B8: 1440 | C8: 240 | D8: 2880 | E8: Execution | F8: Email Security | G8: Rule Deployed | J8: Blocked by Control | K8: Pending SOC Review | L8: Not Red Team - Escalate | O8: T1562.001 | P8: Disable or Modify Tools | Q8: Defense Evasion | S8: =IF(H8="","",H8)
E9: Persistence | F9: Identity / IdP | G9: Validated | O9: T1003.001 | P9: LSASS Memory | Q9: Credential Access | S9: =IF(H9="","",H9)
E10: Privilege Escalation | F10: Cloud | O10: T1087.002 | P10: Domain Account | Q10: Discovery | S10: =IF(H10="","",H10)
A11: Priority threshold | B11: 2 | C11: per technique: events missed or over SLA ≥ this → High priority | E11: Defense Evasion | F11: DLP | O11: T1021.002 | P11: SMB/Windows Admin Shares | Q11: Lateral Movement | S11: =IF(H11="","",H11)
E12: Credential Access | F12: Proxy / SWG | O12: T1071.001 | P12: Web Protocols | Q12: Command and Control | S12: =IF(H12="","",H12)
E13: Discovery | F13: Firewall
E14: Lateral Movement | F14: Other
E15: Collection
E16: Command and Control
E17: Exfiltration
E18: Impact

Sheet Activity & Event Log
A1: Red Team Activity & Event Log
A2: Single log. One row per activity. Detection A-W / Containment X-AJ / Operator & Deconfliction AK-AU. A row counts on the dashboard only when Severity (col G) is filled — that marks it a measured event. Pure activity steps: leave Severity blank. Rows 5-19 are SAMPLE placeholders.
X3: CONTAINMENT INPUTS | AC3: CONTAINMENT CALCULATED | AK3: OPERATOR & DECONFLICTION
A4: Event ID | B4: Engagement | C4: MITRE Tactic | D4: Technique ID | E4: Event Description | F4: Target Asset | G4: Severity | H4: Expected Detection Source | I4: Action Executed (Clock Start) | J4: Telemetry Logged | K4: Alert Generated | L4: Alert Surfaced to IR (Clock Stop) | M4: Detection Rule / Ticket | N4: Remediation Status | O4: Notes | P4: Telemetry Latency (min) | Q4: Alert Gen Latency (min) | R4: Triage Latency (min) | S4: Time-to-Detection (min) | T4: TTD SLA Target (min) | U4: Within SLA? | V4: Detection Result | W4: Detected? (1/0) | X4: Containment Action Started (Clock Start) | Y4: Host Isolated | Z4: C2 Blocked (Clock Stop) | AA4: Containment Owner / Team | AB4: Containment Notes | AC4: Response Init Latency (min) | AD4: Host Isolation Latency (min) | AE4: C2 Disruption Latency (min) | AF4: Time-to-Containment (min) | AG4: Containment SLA Target (min) | AH4: Within Cont. SLA? | AI4: Containment Result | AJ4: Contained? (1/0) | AK4: Operator | AL4: Source Host / IP | AM4: Command / Procedure | AN4: Tool / C2 | AO4: Worked? (Y/N) | AP4: Result / Observation | AQ4: Deconfliction Status | AR4: Reported By (White Cell) | AS4: Cleanup Status | AT4: Cleanup Notes | AU4: Comments
A5: RT-001 | B5: Q2-2026 Engagement | C5: Initial Access | D5: T1566.001 | E5: Sample event 01 (placeholder) | F5: HOST-01 | G5: High | H5: Email Security | I5: 46154.375 | J5: 46154.376 | K5: 46154.378 | L5: 46154.411 | N5: Not Required | P5: =IF(AND(G5<>"",I5<>"",J5<>""),(J5-I5)*1440,"") -> 1 | Q5: =IF(AND(G5<>"",J5<>"",K5<>""),(K5-J5)*1440,"") -> 3 | R5: =IF(AND(G5<>"",K5<>"",L5<>""),(L5-K5)*1440,"") -> 48 | S5: =IF(AND(G5<>"",I5<>"",L5<>""),(L5-I5)*1440,"") -> 52 | T5: =IF(G5="","",IFERROR(INDEX(Settings!$B$5:$B$8,MATCH(G5,Settings!$A$5:$A$8,0)),"")) -> 60 | U5: =IF(G5="","",IF(S5="","No",IF(S5<=T5,"Yes","No"))) -> Yes | V5: =IF(G5="","",IF(AND(J5="",K5="",L5=""),"Telemetry Blind Spot",IF(AND(K5="",L5=""),"Missed Alert",IF(L5="","Triage Delay",IF(S5<=T5,"Detected - Within SLA",IF(AND(R5<>"",R5>IFERROR(INDEX(Settings!$C$5:$C$8,MATCH(G5,Settings!$A$5:$A$8,0)),1E+099)),"Triage Delay","Detected - SLA Breach")))))) -> Detected - Within SLA | W5: =IF(G5="","",IF(L5<>"",1,0)) -> 1 | X5: 46154.418 | Y5: 46154.435 | Z5: 46154.474 | AA5: IR Team | AC5: =IF(AND(G5<>"",L5<>"",X5<>""),(X5-L5)*1440,"") -> 10 | AD5: =IF(AND(G5<>"",X5<>"",Y5<>""),(Y5-X5)*1440,"") -> 25 | AE5: =IF(AND(G5<>"",Y5<>"",Z5<>""),(Z5-Y5)*1440,"") -> 55 | AF5: =IF(AND(G5<>"",L5<>"",Z5<>""),(Z5-L5)*1440,"") -> 90 | AG5: =IF(G5="","",IFERROR(INDEX(Settings!$D$5:$D$8,MATCH(G5,Settings!$A$5:$A$8,0)),"")) -> 240 | AH5: =IF(G5="","",IF(AF5="","No",IF(AF5<=AG5,"Yes","No"))) -> Yes | AI5: =IF(G5="","",IF(L5="","N/A - Not Detected",IF(AND(X5="",Y5="",Z5=""),"No Containment Action",IF(Z5="",IF(Y5<>"","C2 Persisted","Host Isolation Gap"),IF(AF5<=AG5,"Contained - Within SLA","Contained - SLA Breach"))))) -> Contained - Within SLA | AJ5: =IF(G5="","",IF(Z5<>"",1,0)) -> 1 | AK5: operator1 | AL5: 10.0.0.1 | AM5: <command / procedure> | AN5: <tool / C2> | AO5: Y | AP5: Sample observation (placeholder) | AQ5: Not Required | AR5: White Cell | AS5: Complete | AU5: Example row - clear before real use
A6: RT-002 | B6: Q2-2026 Engagement | C6: Execution | D6: T1059.001 | E6: Sample event 02 (placeholder) | F6: HOST-02 | G6: Critical | H6: EDR | I6: 46154.408 | J6: 46154.408 | K6: 46154.409 | L6: 46154.434 | N6: Not Required | P6: =IF(AND(G6<>"",I6<>"",J6<>""),(J6-I6)*1440,"") -> 0.5 | Q6: =IF(AND(G6<>"",J6<>"",K6<>""),(K6-J6)*1440,"") -> 1.5 | R6: =IF(AND(G6<>"",K6<>"",L6<>""),(L6-K6)*1440,"") -> 36 | S6: =IF(AND(G6<>"",I6<>"",L6<>""),(L6-I6)*1440,"") -> 38 | T6: =IF(G6="","",IFERROR(INDEX(Settings!$B$5:$B$8,MATCH(G6,Settings!$A$5:$A$8,0)),"")) -> 15 | U6: =IF(G6="","",IF(S6="","No",IF(S6<=T6,"Yes","No"))) -> No | V6: =IF(G6="","",IF(AND(J6="",K6="",L6=""),"Telemetry Blind Spot",IF(AND(K6="",L6=""),"Missed Alert",IF(L6="","Triage Delay",IF(S6<=T6,"Detected - Within SLA",IF(AND(R6<>"",R6>IFERROR(INDEX(Settings!$C$5:$C$8,MATCH(G6,Settings!$A$5:$A$8,0)),1E+099)),"Triage Delay","Detected - SLA Breach")))))) -> Triage Delay | W6: =IF(G6="","",IF(L6<>"",1,0)) -> 1 | X6: 46154.444 | Y6: 46154.476 | AA6: IR Team | AC6: =IF(AND(G6<>"",L6<>"",X6<>""),(X6-L6)*1440,"") -> 15 | AD6: =IF(AND(G6<>"",X6<>"",Y6<>""),(Y6-X6)*1440,"") -> 45 | AE6: =IF(AND(G6<>"",Y6<>"",Z6<>""),(Z6-Y6)*1440,"") | AF6: =IF(AND(G6<>"",L6<>"",Z6<>""),(Z6-L6)*1440,"") | AG6: =IF(G6="","",IFERROR(INDEX(Settings!$D$5:$D$8,MATCH(G6,Settings!$A$5:$A$8,0)),"")) -> 60 | AH6: =IF(G6="","",IF(AF6="","No",IF(AF6<=AG6,"Yes","No"))) -> No | AI6: =IF(G6="","",IF(L6="","N/A - Not Detected",IF(AND(X6="",Y6="",Z6=""),"No Containment Action",IF(Z6="",IF(Y6<>"","C2 Persisted","Host Isolation Gap"),IF(AF6<=AG6,"Contained - Within SLA","Contained - SLA Breach"))))) -> C2 Persisted | AJ6: =IF(G6="","",IF(Z6<>"",1,0)) -> 0 | AK6: operator1 | AL6: 10.0.0.2 | AM6: <command / procedure> | AN6: <tool / C2> | AO6: Y | AP6: Sample observation (placeholder) | AQ6: Not Required | AR6: White Cell | AS6: Complete | AU6: Example row - clear before real use
A7: RT-003 | B7: Q2-2026 Engagement | C7: Persistence | D7: T1053.005 | E7: Sample event 03 (placeholder) | F7: HOST-03 | G7: High | H7: EDR | I7: 46154.44 | J7: 46154.441 | M7: DE-1003 | N7: Validated | P7: =IF(AND(G7<>"",I7<>"",J7<>""),(J7-I7)*1440,"") -> 1 | Q7: =IF(AND(G7<>"",J7<>"",K7<>""),(K7-J7)*1440,"") | R7: =IF(AND(G7<>"",K7<>"",L7<>""),(L7-K7)*1440,"") | S7: =IF(AND(G7<>"",I7<>"",L7<>""),(L7-I7)*1440,"") | T7: =IF(G7="","",IFERROR(INDEX(Settings!$B$5:$B$8,MATCH(G7,Settings!$A$5:$A$8,0)),"")) -> 60 | U7: =IF(G7="","",IF(S7="","No",IF(S7<=T7,"Yes","No"))) -> No | V7: =IF(G7="","",IF(AND(J7="",K7="",L7=""),"Telemetry Blind Spot",IF(AND(K7="",L7=""),"Missed Alert",IF(L7="","Triage Delay",IF(S7<=T7,"Detected - Within SLA",IF(AND(R7<>"",R7>IFERROR(INDEX(Settings!$C$5:$C$8,MATCH(G7,Settings!$A$5:$A$8,0)),1E+099)),"Triage Delay","Detected - SLA Breach")))))) -> Missed Alert | W7: =IF(G7="","",IF(L7<>"",1,0)) -> 0 | AC7: =IF(AND(G7<>"",L7<>"",X7<>""),(X7-L7)*1440,"") | AD7: =IF(AND(G7<>"",X7<>"",Y7<>""),(Y7-X7)*1440,"") | AE7: =IF(AND(G7<>"",Y7<>"",Z7<>""),(Z7-Y7)*1440,"") | AF7: =IF(AND(G7<>"",L7<>"",Z7<>""),(Z7-L7)*1440,"") | AG7: =IF(G7="","",IFERROR(INDEX(Settings!$D$5:$D$8,MATCH(G7,Settings!$A$5:$A$8,0)),"")) -> 240 | AH7: =IF(G7="","",IF(AF7="","No",IF(AF7<=AG7,"Yes","No"))) -> No | AI7: =IF(G7="","",IF(L7="","N/A - Not Detected",IF(AND(X7="",Y7="",Z7=""),"No Containment Action",IF(Z7="",IF(Y7<>"","C2 Persisted","Host Isolation Gap"),IF(AF7<=AG7,"Contained - Within SLA","Contained - SLA Breach"))))) -> N/A - Not Detected | AJ7: =IF(G7="","",IF(Z7<>"",1,0)) -> 0 | AK7: operator1 | AL7: 10.0.0.3 | AM7: <command / procedure> | AN7: <tool / C2> | AO7: Y | AP7: Sample observation (placeholder) | AQ7: Pending | AR7: White Cell | AS7: Pending | AU7: Example row - clear before real use
A8: RT-004 | B8: Q2-2026 Engagement | C8: Defense Evasion | D8: T1562.001 | E8: Sample event 04 (placeholder) | F8: HOST-04 | G8: Critical | H8: EDR | I8: 46154.473 | J8: 46154.473 | K8: 46154.474 | L8: 46154.479 | N8: Not Required | P8: =IF(AND(G8<>"",I8<>"",J8<>""),(J8-I8)*1440,"") -> 0.5 | Q8: =IF(AND(G8<>"",J8<>"",K8<>""),(K8-J8)*1440,"") -> 0.5 | R8: =IF(AND(G8<>"",K8<>"",L8<>""),(L8-K8)*1440,"") -> 8 | S8: =IF(AND(G8<>"",I8<>"",L8<>""),(L8-I8)*1440,"") -> 9 | T8: =IF(G8="","",IFERROR(INDEX(Settings!$B$5:$B$8,MATCH(G8,Settings!$A$5:$A$8,0)),"")) -> 15 | U8: =IF(G8="","",IF(S8="","No",IF(S8<=T8,"Yes","No"))) -> Yes | V8: =IF(G8="","",IF(AND(J8="",K8="",L8=""),"Telemetry Blind Spot",IF(AND(K8="",L8=""),"Missed Alert",IF(L8="","Triage Delay",IF(S8<=T8,"Detected - Within SLA",IF(AND(R8<>"",R8>IFERROR(INDEX(Settings!$C$5:$C$8,MATCH(G8,Settings!$A$5:$A$8,0)),1E+099)),"Triage Delay","Detected - SLA Breach")))))) -> Detected - Within SLA | W8: =IF(G8="","",IF(L8<>"",1,0)) -> 1 | X8: 46154.483 | Y8: 46154.493 | Z8: 46154.5 | AA8: IR Team | AC8: =IF(AND(G8<>"",L8<>"",X8<>""),(X8-L8)*1440,"") -> 5 | AD8: =IF(AND(G8<>"",X8<>"",Y8<>""),(Y8-X8)*1440,"") -> 15 | AE8: =IF(AND(G8<>"",Y8<>"",Z8<>""),(Z8-Y8)*1440,"") -> 10 | AF8: =IF(AND(G8<>"",L8<>"",Z8<>""),(Z8-L8)*1440,"") -> 30 | AG8: =IF(G8="","",IFERROR(INDEX(Settings!$D$5:$D$8,MATCH(G8,Settings!$A$5:$A$8,0)),"")) -> 60 | AH8: =IF(G8="","",IF(AF8="","No",IF(AF8<=AG8,"Yes","No"))) -> Yes | AI8: =IF(G8="","",IF(L8="","N/A - Not Detected",IF(AND(X8="",Y8="",Z8=""),"No Containment Action",IF(Z8="",IF(Y8<>"","C2 Persisted","Host Isolation Gap"),IF(AF8<=AG8,"Contained - Within SLA","Contained - SLA Breach"))))) -> Contained - Within SLA | AJ8: =IF(G8="","",IF(Z8<>"",1,0)) -> 1 | AK8: operator1 | AL8: 10.0.0.4 | AM8: <command / procedure> | AN8: <tool / C2> | AO8: Y | AP8: Sample observation (placeholder) | AQ8: Not Required | AR8: White Cell | AS8: Complete | AU8: Example row - clear before real use
A9: RT-005 | B9: Q2-2026 Engagement | C9: Credential Access | D9: T1003.001 | E9: Sample event 05 (placeholder) | F9: HOST-05 | G9: Critical | H9: Identity / IdP | I9: 46154.506 | J9: 46154.507 | K9: 46154.51 | L9: 46154.572 | N9: Not Required | P9: =IF(AND(G9<>"",I9<>"",J9<>""),(J9-I9)*1440,"") -> 2 | Q9: =IF(AND(G9<>"",J9<>"",K9<>""),(K9-J9)*1440,"") -> 4 | R9: =IF(AND(G9<>"",K9<>"",L9<>""),(L9-K9)*1440,"") -> 89 | S9: =IF(AND(G9<>"",I9<>"",L9<>""),(L9-I9)*1440,"") -> 95 | T9: =IF(G9="","",IFERROR(INDEX(Settings!$B$5:$B$8,MATCH(G9,Settings!$A$5:$A$8,0)),"")) -> 15 | U9: =IF(G9="","",IF(S9="","No",IF(S9<=T9,"Yes","No"))) -> No | V9: =IF(G9="","",IF(AND(J9="",K9="",L9=""),"Telemetry Blind Spot",IF(AND(K9="",L9=""),"Missed Alert",IF(L9="","Triage Delay",IF(S9<=T9,"Detected - Within SLA",IF(AND(R9<>"",R9>IFERROR(INDEX(Settings!$C$5:$C$8,MATCH(G9,Settings!$A$5:$A$8,0)),1E+099)),"Triage Delay","Detected - SLA Breach")))))) -> Triage Delay | W9: =IF(G9="","",IF(L9<>"",1,0)) -> 1 | X9: 46154.599 | AA9: IR Team | AC9: =IF(AND(G9<>"",L9<>"",X9<>""),(X9-L9)*1440,"") -> 40 | AD9: =IF(AND(G9<>"",X9<>"",Y9<>""),(Y9-X9)*1440,"") | AE9: =IF(AND(G9<>"",Y9<>"",Z9<>""),(Z9-Y9)*1440,"") | AF9: =IF(AND(G9<>"",L9<>"",Z9<>""),(Z9-L9)*1440,"") | AG9: =IF(G9="","",IFERROR(INDEX(Settings!$D$5:$D$8,MATCH(G9,Settings!$A$5:$A$8,0)),"")) -> 60 | AH9: =IF(G9="","",IF(AF9="","No",IF(AF9<=AG9,"Yes","No"))) -> No | AI9: =IF(G9="","",IF(L9="","N/A - Not Detected",IF(AND(X9="",Y9="",Z9=""),"No Containment Action",IF(Z9="",IF(Y9<>"","C2 Persisted","Host Isolation Gap"),IF(AF9<=AG9,"Contained - Within SLA","Contained - SLA Breach"))))) -> Host Isolation Gap | AJ9: =IF(G9="","",IF(Z9<>"",1,0)) -> 0 | AK9: operator1 | AL9: 10.0.0.5 | AM9: <command / procedure> | AN9: <tool / C2> | AO9: Y | AP9: Sample observation (placeholder) | AQ9: Not Required | AR9: White Cell | AS9: Complete | AU9: Example row - clear before real use
A10: RT-006 | B10: Q2-2026 Engagement | C10: Discovery | D10: T1087.002 | E10: Sample event 06 (placeholder) | F10: HOST-06 | G10: Medium | H10: SIEM | I10: 46154.538 | M10: DE-1006 | N10: Validated | P10: =IF(AND(G10<>"",I10<>"",J10<>""),(J10-I10)*1440,"") | Q10: =IF(AND(G10<>"",J10<>"",K10<>""),(K10-J10)*1440,"") | R10: =IF(AND(G10<>"",K10<>"",L10<>""),(L10-K10)*1440,"") | S10: =IF(AND(G10<>"",I10<>"",L10<>""),(L10-I10)*1440,"") | T10: =IF(G10="","",IFERROR(INDEX(Settings!$B$5:$B$8,MATCH(G10,Settings!$A$5:$A$8,0)),"")) -> 240 | U10: =IF(G10="","",IF(S10="","No",IF(S10<=T10,"Yes","No"))) -> No | V10: =IF(G10="","",IF(AND(J10="",K10="",L10=""),"Telemetry Blind Spot",IF(AND(K10="",L10=""),"Missed Alert",IF(L10="","Triage Delay",IF(S10<=T10,"Detected - Within SLA",IF(AND(R10<>"",R10>IFERROR(INDEX(Settings!$C$5:$C$8,MATCH(G10,Settings!$A$5:$A$8,0)),1E+099)),"Triage Delay","Detected - SLA Breach")))))) -> Telemetry Blind Spot | W10: =IF(G10="","",IF(L10<>"",1,0)) -> 0 | AC10: =IF(AND(G10<>"",L10<>"",X10<>""),(X10-L10)*1440,"") | AD10: =IF(AND(G10<>"",X10<>"",Y10<>""),(Y10-X10)*1440,"") | AE10: =IF(AND(G10<>"",Y10<>"",Z10<>""),(Z10-Y10)*1440,"") | AF10: =IF(AND(G10<>"",L10<>"",Z10<>""),(Z10-L10)*1440,"") | AG10: =IF(G10="","",IFERROR(INDEX(Settings!$D$5:$D$8,MATCH(G10,Settings!$A$5:$A$8,0)),"")) -> 1440 | AH10: =IF(G10="","",IF(AF10="","No",IF(AF10<=AG10,"Yes","No"))) -> No | AI10: =IF(G10="","",IF(L10="","N/A - Not Detected",IF(AND(X10="",Y10="",Z10=""),"No Containment Action",IF(Z10="",IF(Y10<>"","C2 Persisted","Host Isolation Gap"),IF(AF10<=AG10,"Contained - Within SLA","Contained - SLA Breach"))))) -> N/A - Not Detected | AJ10: =IF(G10="","",IF(Z10<>"",1,0)) -> 0 | AK10: operator1 | AL10: 10.0.0.6 | AM10: <command / procedure> | AN10: <tool / C2> | AO10: Y | AP10: Sample observation (placeholder) | AQ10: Pending | AR10: White Cell | AS10: Pending | AU10: Example row - clear before real use
A11: RT-007 | B11: Q2-2026 Engagement | C11: Lateral Movement | D11: T1021.002 | E11: Sample event 07 (placeholder) | F11: HOST-07 | G11: High | H11: SIEM | I11: 46154.571 | J11: 46154.573 | K11: 46154.578 | L11: 46154.668 | N11: Not Required | P11: =IF(AND(G11<>"",I11<>"",J11<>""),(J11-I11)*1440,"") -> 3 | Q11: =IF(AND(G11<>"",J11<>"",K11<>""),(K11-J11)*1440,"") -> 8 | R11: =IF(AND(G11<>"",K11<>"",L11<>""),(L11-K11)*1440,"") -> 129 | S11: =IF(AND(G11<>"",I11<>"",L11<>""),(L11-I11)*1440,"") -> 140 | T11: =IF(G11="","",IFERROR(INDEX(Settings!$B$5:$B$8,MATCH(G11,Settings!$A$5:$A$8,0)),"")) -> 60 | U11: =IF(G11="","",IF(S11="","No",IF(S11<=T11,"Yes","No"))) -> No | V11: =IF(G11="","",IF(AND(J11="",K11="",L11=""),"Telemetry Blind Spot",IF(AND(K11="",L11=""),"Missed Alert",IF(L11="","Triage Delay",IF(S11<=T11,"Detected - Within SLA",IF(AND(R11<>"",R11>IFERROR(INDEX(Settings!$C$5:$C$8,MATCH(G11,Settings!$A$5:$A$8,0)),1E+099)),"Triage Delay","Detected - SLA Breach")))))) -> Triage Delay | W11: =IF(G11="","",IF(L11<>"",1,0)) -> 1 | X11: 46154.682 | Y11: 46154.703 | Z11: 46154.751 | AA11: IR Team | AC11: =IF(AND(G11<>"",L11<>"",X11<>""),(X11-L11)*1440,"") -> 20 | AD11: =IF(AND(G11<>"",X11<>"",Y11<>""),(Y11-X11)*1440,"") -> 30 | AE11: =IF(AND(G11<>"",Y11<>"",Z11<>""),(Z11-Y11)*1440,"") -> 70 | AF11: =IF(AND(G11<>"",L11<>"",Z11<>""),(Z11-L11)*1440,"") -> 120 | AG11: =IF(G11="","",IFERROR(INDEX(Settings!$D$5:$D$8,MATCH(G11,Settings!$A$5:$A$8,0)),"")) -> 240 | AH11: =IF(G11="","",IF(AF11="","No",IF(AF11<=AG11,"Yes","No"))) -> Yes | AI11: =IF(G11="","",IF(L11="","N/A - Not Detected",IF(AND(X11="",Y11="",Z11=""),"No Containment Action",IF(Z11="",IF(Y11<>"","C2 Persisted","Host Isolation Gap"),IF(AF11<=AG11,"Contained - Within SLA","Contained - SLA Breach"))))) -> Contained - Within SLA | AJ11: =IF(G11="","",IF(Z11<>"",1,0)) -> 1 | AK11: operator1 | AL11: 10.0.0.7 | AM11: <command / procedure> | AN11: <tool / C2> | AO11: Y | AP11: Sample observation (placeholder) | AQ11: Not Required | AR11: White Cell | AS11: Complete | AU11: Example row - clear before real use
A12: RT-008 | B12: Q2-2026 Engagement | C12: Command and Control | D12: T1071.001 | E12: Sample event 08 (placeholder) | F12: HOST-08 | G12: High | H12: NDR | I12: 46154.603 | M12: DE-1008 | N12: Validated | P12: =IF(AND(G12<>"",I12<>"",J12<>""),(J12-I12)*1440,"") | Q12: =IF(AND(G12<>"",J12<>"",K12<>""),(K12-J12)*1440,"") | R12: =IF(AND(G12<>"",K12<>"",L12<>""),(L12-K12)*1440,"") | S12: =IF(AND(G12<>"",I12<>"",L12<>""),(L12-I12)*1440,"") | T12: =IF(G12="","",IFERROR(INDEX(Settings!$B$5:$B$8,MATCH(G12,Settings!$A$5:$A$8,0)),"")) -> 60 | U12: =IF(G12="","",IF(S12="","No",IF(S12<=T12,"Yes","No"))) -> No | V12: =IF(G12="","",IF(AND(J12="",K12="",L12=""),"Telemetry Blind Spot",IF(AND(K12="",L12=""),"Missed Alert",IF(L12="","Triage Delay",IF(S12<=T12,"Detected - Within SLA",IF(AND(R12<>"",R12>IFERROR(INDEX(Settings!$C$5:$C$8,MATCH(G12,Settings!$A$5:$A$8,0)),1E+099)),"Triage Delay","Detected - SLA Breach")))))) -> Telemetry Blind Spot | W12: =IF(G12="","",IF(L12<>"",1,0)) -> 0 | AC12: =IF(AND(G12<>"",L12<>"",X12<>""),(X12-L12)*1440,"") | AD12: =IF(AND(G12<>"",X12<>"",Y12<>""),(Y12-X12)*1440,"") | AE12: =IF(AND(G12<>"",Y12<>"",Z12<>""),(Z12-Y12)*1440,"") | AF12: =IF(AND(G12<>"",L12<>"",Z12<>""),(Z12-L12)*1440,"") | AG12: =IF(G12="","",IFERROR(INDEX(Settings!$D$5:$D$8,MATCH(G12,Settings!$A$5:$A$8,0)),"")) -> 240 | AH12: =IF(G12="","",IF(AF12="","No",IF(AF12<=AG12,"Yes","No"))) -> No | AI12: =IF(G12="","",IF(L12="","N/A - Not Detected",IF(AND(X12="",Y12="",Z12=""),"No Containment Action",IF(Z12="",IF(Y12<>"","C2 Persisted","Host Isolation Gap"),IF(AF12<=AG12,"Contained - Within SLA","Contained - SLA Breach"))))) -> N/A - Not Detected | AJ12: =IF(G12="","",IF(Z12<>"",1,0)) -> 0 | AK12: operator1 | AL12: 10.0.0.8 | AM12: <command / procedure> | AN12: <tool / C2> | AO12: Y | AP12: Sample observation (placeholder) | AQ12: Pending | AR12: White Cell | AS12: Pending | AU12: Example row - clear before real use
A13: RT-009 | B13: Q3-2026 Engagement | C13: Initial Access | D13: T1566.001 | E13: Sample event 09 (placeholder) | F13: HOST-09 | G13: High | H13: Email Security | I13: 46252.375 | J13: 46252.376 | K13: 46252.377 | L13: 46252.39 | N13: Not Required | P13: =IF(AND(G13<>"",I13<>"",J13<>""),(J13-I13)*1440,"") -> 1 | Q13: =IF(AND(G13<>"",J13<>"",K13<>""),(K13-J13)*1440,"") -> 2 | R13: =IF(AND(G13<>"",K13<>"",L13<>""),(L13-K13)*1440,"") -> 18 | S13: =IF(AND(G13<>"",I13<>"",L13<>""),(L13-I13)*1440,"") -> 21 | T13: =IF(G13="","",IFERROR(INDEX(Settings!$B$5:$B$8,MATCH(G13,Settings!$A$5:$A$8,0)),"")) -> 60 | U13: =IF(G13="","",IF(S13="","No",IF(S13<=T13,"Yes","No"))) -> Yes | V13: =IF(G13="","",IF(AND(J13="",K13="",L13=""),"Telemetry Blind Spot",IF(AND(K13="",L13=""),"Missed Alert",IF(L13="","Triage Delay",IF(S13<=T13,"Detected - Within SLA",IF(AND(R13<>"",R13>IFERROR(INDEX(Settings!$C$5:$C$8,MATCH(G13,Settings!$A$5:$A$8,0)),1E+099)),"Triage Delay","Detected - SLA Breach")))))) -> Detected - Within SLA | W13: =IF(G13="","",IF(L13<>"",1,0)) -> 1 | X13: 46252.393 | Y13: 46252.4 | Z13: 46252.41 | AA13: IR Team | AC13: =IF(AND(G13<>"",L13<>"",X13<>""),(X13-L13)*1440,"") -> 5 | AD13: =IF(AND(G13<>"",X13<>"",Y13<>""),(Y13-X13)*1440,"") -> 10 | AE13: =IF(AND(G13<>"",Y13<>"",Z13<>""),(Z13-Y13)*1440,"") -> 15 | AF13: =IF(AND(G13<>"",L13<>"",Z13<>""),(Z13-L13)*1440,"") -> 30 | AG13: =IF(G13="","",IFERROR(INDEX(Settings!$D$5:$D$8,MATCH(G13,Settings!$A$5:$A$8,0)),"")) -> 240 | AH13: =IF(G13="","",IF(AF13="","No",IF(AF13<=AG13,"Yes","No"))) -> Yes | AI13: =IF(G13="","",IF(L13="","N/A - Not Detected",IF(AND(X13="",Y13="",Z13=""),"No Containment Action",IF(Z13="",IF(Y13<>"","C2 Persisted","Host Isolation Gap"),IF(AF13<=AG13,"Contained - Within SLA","Contained - SLA Breach"))))) -> Contained - Within SLA | AJ13: =IF(G13="","",IF(Z13<>"",1,0)) -> 1 | AK13: operator1 | AL13: 10.0.0.9 | AM13: <command / procedure> | AN13: <tool / C2> | AO13: Y | AP13: Sample observation (placeholder) | AQ13: Not Required | AR13: White Cell | AS13: Complete | AU13: Example row - clear before real use
A14: RT-010 | B14: Q3-2026 Engagement | C14: Execution | D14: T1059.001 | E14: Sample event 10 (placeholder) | F14: HOST-10 | G14: Critical | H14: EDR | I14: 46252.408 | J14: 46252.408 | K14: 46252.409 | L14: 46252.412 | N14: Not Required | P14: =IF(AND(G14<>"",I14<>"",J14<>""),(J14-I14)*1440,"") -> 0.5 | Q14: =IF(AND(G14<>"",J14<>"",K14<>""),(K14-J14)*1440,"") -> 1 | R14: =IF(AND(G14<>"",K14<>"",L14<>""),(L14-K14)*1440,"") -> 5.5 | S14: =IF(AND(G14<>"",I14<>"",L14<>""),(L14-I14)*1440,"") -> 7 | T14: =IF(G14="","",IFERROR(INDEX(Settings!$B$5:$B$8,MATCH(G14,Settings!$A$5:$A$8,0)),"")) -> 15 | U14: =IF(G14="","",IF(S14="","No",IF(S14<=T14,"Yes","No"))) -> Yes | V14: =IF(G14="","",IF(AND(J14="",K14="",L14=""),"Telemetry Blind Spot",IF(AND(K14="",L14=""),"Missed Alert",IF(L14="","Triage Delay",IF(S14<=T14,"Detected - Within SLA",IF(AND(R14<>"",R14>IFERROR(INDEX(Settings!$C$5:$C$8,MATCH(G14,Settings!$A$5:$A$8,0)),1E+099)),"Triage Delay","Detected - SLA Breach")))))) -> Detected - Within SLA | W14: =IF(G14="","",IF(L14<>"",1,0)) -> 1 | X14: 46252.414 | Y14: 46252.418 | Z14: 46252.425 | AA14: IR Team | AC14: =IF(AND(G14<>"",L14<>"",X14<>""),(X14-L14)*1440,"") -> 2 | AD14: =IF(AND(G14<>"",X14<>"",Y14<>""),(Y14-X14)*1440,"") -> 6 | AE14: =IF(AND(G14<>"",Y14<>"",Z14<>""),(Z14-Y14)*1440,"") -> 10 | AF14: =IF(AND(G14<>"",L14<>"",Z14<>""),(Z14-L14)*1440,"") -> 18 | AG14: =IF(G14="","",IFERROR(INDEX(Settings!$D$5:$D$8,MATCH(G14,Settings!$A$5:$A$8,0)),"")) -> 60 | AH14: =IF(G14="","",IF(AF14="","No",IF(AF14<=AG14,"Yes","No"))) -> Yes | AI14: =IF(G14="","",IF(L14="","N/A - Not Detected",IF(AND(X14="",Y14="",Z14=""),"No Containment Action",IF(Z14="",IF(Y14<>"","C2 Persisted","Host Isolation Gap"),IF(AF14<=AG14,"Contained - Within SLA","Contained - SLA Breach"))))) -> Contained - Within SLA | AJ14: =IF(G14="","",IF(Z14<>"",1,0)) -> 1 | AK14: operator1 | AL14: 10.0.0.10 | AM14: <command / procedure> | AN14: <tool / C2> | AO14: Y | AP14: Sample observation (placeholder) | AQ14: Not Required | AR14: White Cell | AS14: Complete | AU14: Example row - clear before real use
A15: RT-011 | B15: Q3-2026 Engagement | C15: Persistence | D15: T1053.005 | E15: Sample event 11 (placeholder) | F15: HOST-11 | G15: High | H15: EDR | I15: 46252.44 | J15: 46252.441 | K15: 46252.442 | L15: 46252.458 | N15: Not Required | P15: =IF(AND(G15<>"",I15<>"",J15<>""),(J15-I15)*1440,"") -> 1 | Q15: =IF(AND(G15<>"",J15<>"",K15<>""),(K15-J15)*1440,"") -> 2 | R15: =IF(AND(G15<>"",K15<>"",L15<>""),(L15-K15)*1440,"") -> 22 | S15: =IF(AND(G15<>"",I15<>"",L15<>""),(L15-I15)*1440,"") -> 25 | T15: =IF(G15="","",IFERROR(INDEX(Settings!$B$5:$B$8,MATCH(G15,Settings!$A$5:$A$8,0)),"")) -> 60 | U15: =IF(G15="","",IF(S15="","No",IF(S15<=T15,"Yes","No"))) -> Yes | V15: =IF(G15="","",IF(AND(J15="",K15="",L15=""),"Telemetry Blind Spot",IF(AND(K15="",L15=""),"Missed Alert",IF(L15="","Triage Delay",IF(S15<=T15,"Detected - Within SLA",IF(AND(R15<>"",R15>IFERROR(INDEX(Settings!$C$5:$C$8,MATCH(G15,Settings!$A$5:$A$8,0)),1E+099)),"Triage Delay","Detected - SLA Breach")))))) -> Detected - Within SLA | W15: =IF(G15="","",IF(L15<>"",1,0)) -> 1 | X15: 46252.461 | Y15: 46252.466 | Z15: 46252.485 | AA15: IR Team | AC15: =IF(AND(G15<>"",L15<>"",X15<>""),(X15-L15)*1440,"") -> 5 | AD15: =IF(AND(G15<>"",X15<>"",Y15<>""),(Y15-X15)*1440,"") -> 7 | AE15: =IF(AND(G15<>"",Y15<>"",Z15<>""),(Z15-Y15)*1440,"") -> 28 | AF15: =IF(AND(G15<>"",L15<>"",Z15<>""),(Z15-L15)*1440,"") -> 40 | AG15: =IF(G15="","",IFERROR(INDEX(Settings!$D$5:$D$8,MATCH(G15,Settings!$A$5:$A$8,0)),"")) -> 240 | AH15: =IF(G15="","",IF(AF15="","No",IF(AF15<=AG15,"Yes","No"))) -> Yes | AI15: =IF(G15="","",IF(L15="","N/A - Not Detected",IF(AND(X15="",Y15="",Z15=""),"No Containment Action",IF(Z15="",IF(Y15<>"","C2 Persisted","Host Isolation Gap"),IF(AF15<=AG15,"Contained - Within SLA","Contained - SLA Breach"))))) -> Contained - Within SLA | AJ15: =IF(G15="","",IF(Z15<>"",1,0)) -> 1 | AK15: operator1 | AL15: 10.0.0.11 | AM15: <command / procedure> | AN15: <tool / C2> | AO15: Y | AP15: Sample observation (placeholder) | AQ15: Not Required | AR15: White Cell | AS15: Complete | AU15: Example row - clear before real use
A16: RT-012 | B16: Q3-2026 Engagement | C16: Defense Evasion | D16: T1562.001 | E16: Sample event 12 (placeholder) | F16: HOST-12 | G16: Critical | H16: EDR | I16: 46252.473 | J16: 46252.473 | K16: 46252.474 | L16: 46252.477 | N16: Not Required | P16: =IF(AND(G16<>"",I16<>"",J16<>""),(J16-I16)*1440,"") -> 0.5 | Q16: =IF(AND(G16<>"",J16<>"",K16<>""),(K16-J16)*1440,"") -> 0.5 | R16: =IF(AND(G16<>"",K16<>"",L16<>""),(L16-K16)*1440,"") -> 5 | S16: =IF(AND(G16<>"",I16<>"",L16<>""),(L16-I16)*1440,"") -> 6 | T16: =IF(G16="","",IFERROR(INDEX(Settings!$B$5:$B$8,MATCH(G16,Settings!$A$5:$A$8,0)),"")) -> 15 | U16: =IF(G16="","",IF(S16="","No",IF(S16<=T16,"Yes","No"))) -> Yes | V16: =IF(G16="","",IF(AND(J16="",K16="",L16=""),"Telemetry Blind Spot",IF(AND(K16="",L16=""),"Missed Alert",IF(L16="","Triage Delay",IF(S16<=T16,"Detected - Within SLA",IF(AND(R16<>"",R16>IFERROR(INDEX(Settings!$C$5:$C$8,MATCH(G16,Settings!$A$5:$A$8,0)),1E+099)),"Triage Delay","Detected - SLA Breach")))))) -> Detected - Within SLA | W16: =IF(G16="","",IF(L16<>"",1,0)) -> 1 | X16: 46252.478 | Y16: 46252.481 | Z16: 46252.488 | AA16: IR Team | AC16: =IF(AND(G16<>"",L16<>"",X16<>""),(X16-L16)*1440,"") -> 2 | AD16: =IF(AND(G16<>"",X16<>"",Y16<>""),(Y16-X16)*1440,"") -> 4 | AE16: =IF(AND(G16<>"",Y16<>"",Z16<>""),(Z16-Y16)*1440,"") -> 9 | AF16: =IF(AND(G16<>"",L16<>"",Z16<>""),(Z16-L16)*1440,"") -> 15 | AG16: =IF(G16="","",IFERROR(INDEX(Settings!$D$5:$D$8,MATCH(G16,Settings!$A$5:$A$8,0)),"")) -> 60 | AH16: =IF(G16="","",IF(AF16="","No",IF(AF16<=AG16,"Yes","No"))) -> Yes | AI16: =IF(G16="","",IF(L16="","N/A - Not Detected",IF(AND(X16="",Y16="",Z16=""),"No Containment Action",IF(Z16="",IF(Y16<>"","C2 Persisted","Host Isolation Gap"),IF(AF16<=AG16,"Contained - Within SLA","Contained - SLA Breach"))))) -> Contained - Within SLA | AJ16: =IF(G16="","",IF(Z16<>"",1,0)) -> 1 | AK16: operator1 | AL16: 10.0.0.12 | AM16: <command / procedure> | AN16: <tool / C2> | AO16: Y | AP16: Sample observation (placeholder) | AQ16: Not Required | AR16: White Cell | AS16: Complete | AU16: Example row - clear before real use
A17: RT-013 | B17: Q3-2026 Engagement | C17: Credential Access | D17: T1003.001 | E17: Sample event 13 (placeholder) | F17: HOST-13 | G17: Critical | H17: Identity / IdP | I17: 46252.506 | J17: 46252.507 | K17: 46252.508 | L17: 46252.515 | N17: Not Required | P17: =IF(AND(G17<>"",I17<>"",J17<>""),(J17-I17)*1440,"") -> 2 | Q17: =IF(AND(G17<>"",J17<>"",K17<>""),(K17-J17)*1440,"") -> 2 | R17: =IF(AND(G17<>"",K17<>"",L17<>""),(L17-K17)*1440,"") -> 9 | S17: =IF(AND(G17<>"",I17<>"",L17<>""),(L17-I17)*1440,"") -> 13 | T17: =IF(G17="","",IFERROR(INDEX(Settings!$B$5:$B$8,MATCH(G17,Settings!$A$5:$A$8,0)),"")) -> 15 | U17: =IF(G17="","",IF(S17="","No",IF(S17<=T17,"Yes","No"))) -> Yes | V17: =IF(G17="","",IF(AND(J17="",K17="",L17=""),"Telemetry Blind Spot",IF(AND(K17="",L17=""),"Missed Alert",IF(L17="","Triage Delay",IF(S17<=T17,"Detected - Within SLA",IF(AND(R17<>"",R17>IFERROR(INDEX(Settings!$C$5:$C$8,MATCH(G17,Settings!$A$5:$A$8,0)),1E+099)),"Triage Delay","Detected - SLA Breach")))))) -> Detected - Within SLA | W17: =IF(G17="","",IF(L17<>"",1,0)) -> 1 | X17: 46252.517 | Y17: 46252.522 | Z17: 46252.532 | AA17: IR Team | AC17: =IF(AND(G17<>"",L17<>"",X17<>""),(X17-L17)*1440,"") -> 3 | AD17: =IF(AND(G17<>"",X17<>"",Y17<>""),(Y17-X17)*1440,"") -> 7 | AE17: =IF(AND(G17<>"",Y17<>"",Z17<>""),(Z17-Y17)*1440,"") -> 15 | AF17: =IF(AND(G17<>"",L17<>"",Z17<>""),(Z17-L17)*1440,"") -> 25 | AG17: =IF(G17="","",IFERROR(INDEX(Settings!$D$5:$D$8,MATCH(G17,Settings!$A$5:$A$8,0)),"")) -> 60 | AH17: =IF(G17="","",IF(AF17="","No",IF(AF17<=AG17,"Yes","No"))) -> Yes | AI17: =IF(G17="","",IF(L17="","N/A - Not Detected",IF(AND(X17="",Y17="",Z17=""),"No Containment Action",IF(Z17="",IF(Y17<>"","C2 Persisted","Host Isolation Gap"),IF(AF17<=AG17,"Contained - Within SLA","Contained - SLA Breach"))))) -> Contained - Within SLA | AJ17: =IF(G17="","",IF(Z17<>"",1,0)) -> 1 | AK17: operator1 | AL17: 10.0.0.13 | AM17: <command / procedure> | AN17: <tool / C2> | AO17: Y | AP17: Sample observation (placeholder) | AQ17: Not Required | AR17: White Cell | AS17: Complete | AU17: Example row - clear before real use
A18: RT-014 | B18: Q3-2026 Engagement | C18: Discovery | D18: T1087.002 | E18: Sample event 14 (placeholder) | F18: HOST-14 | G18: Medium | H18: SIEM | I18: 46252.538 | J18: 46252.541 | K18: 46252.549 | L18: 46252.587 | N18: Not Required | P18: =IF(AND(G18<>"",I18<>"",J18<>""),(J18-I18)*1440,"") -> 4 | Q18: =IF(AND(G18<>"",J18<>"",K18<>""),(K18-J18)*1440,"") -> 11 | R18: =IF(AND(G18<>"",K18<>"",L18<>""),(L18-K18)*1440,"") -> 55 | S18: =IF(AND(G18<>"",I18<>"",L18<>""),(L18-I18)*1440,"") -> 70 | T18: =IF(G18="","",IFERROR(INDEX(Settings!$B$5:$B$8,MATCH(G18,Settings!$A$5:$A$8,0)),"")) -> 240 | U18: =IF(G18="","",IF(S18="","No",IF(S18<=T18,"Yes","No"))) -> Yes | V18: =IF(G18="","",IF(AND(J18="",K18="",L18=""),"Telemetry Blind Spot",IF(AND(K18="",L18=""),"Missed Alert",IF(L18="","Triage Delay",IF(S18<=T18,"Detected - Within SLA",IF(AND(R18<>"",R18>IFERROR(INDEX(Settings!$C$5:$C$8,MATCH(G18,Settings!$A$5:$A$8,0)),1E+099)),"Triage Delay","Detected - SLA Breach")))))) -> Detected - Within SLA | W18: =IF(G18="","",IF(L18<>"",1,0)) -> 1 | X18: 46252.594 | Y18: 46252.608 | AA18: IR Team | AC18: =IF(AND(G18<>"",L18<>"",X18<>""),(X18-L18)*1440,"") -> 10 | AD18: =IF(AND(G18<>"",X18<>"",Y18<>""),(Y18-X18)*1440,"") -> 20 | AE18: =IF(AND(G18<>"",Y18<>"",Z18<>""),(Z18-Y18)*1440,"") | AF18: =IF(AND(G18<>"",L18<>"",Z18<>""),(Z18-L18)*1440,"") | AG18: =IF(G18="","",IFERROR(INDEX(Settings!$D$5:$D$8,MATCH(G18,Settings!$A$5:$A$8,0)),"")) -> 1440 | AH18: =IF(G18="","",IF(AF18="","No",IF(AF18<=AG18,"Yes","No"))) -> No | AI18: =IF(G18="","",IF(L18="","N/A - Not Detected",IF(AND(X18="",Y18="",Z18=""),"No Containment Action",IF(Z18="",IF(Y18<>"","C2 Persisted","Host Isolation Gap"),IF(AF18<=AG18,"Contained - Within SLA","Contained - SLA Breach"))))) -> C2 Persisted | AJ18: =IF(G18="","",IF(Z18<>"",1,0)) -> 0 | AK18: operator1 | AL18: 10.0.0.14 | AM18: <command / procedure> | AN18: <tool / C2> | AO18: Y | AP18: Sample observation (placeholder) | AQ18: Not Required | AR18: White Cell | AS18: Complete | AU18: Example row - clear before real use
A19: RT-015 | B19: Q3-2026 Engagement | C19: Lateral Movement | D19: T1021.002 | E19: Sample event 15 (placeholder) | F19: HOST-15 | G19: High | H19: SIEM | I19: 46252.571 | J19: 46252.572 | K19: 46252.576 | L19: 46252.604 | N19: Not Required | P19: =IF(AND(G19<>"",I19<>"",J19<>""),(J19-I19)*1440,"") -> 2 | Q19: =IF(AND(G19<>"",J19<>"",K19<>""),(K19-J19)*1440,"") -> 5 | R19: =IF(AND(G19<>"",K19<>"",L19<>""),(L19-K19)*1440,"") -> 41 | S19: =IF(AND(G19<>"",I19<>"",L19<>""),(L19-I19)*1440,"") -> 48 | T19: =IF(G19="","",IFERROR(INDEX(Settings!$B$5:$B$8,MATCH(G19,Settings!$A$5:$A$8,0)),"")) -> 60 | U19: =IF(G19="","",IF(S19="","No",IF(S19<=T19,"Yes","No"))) -> Yes | V19: =IF(G19="","",IF(AND(J19="",K19="",L19=""),"Telemetry Blind Spot",IF(AND(K19="",L19=""),"Missed Alert",IF(L19="","Triage Delay",IF(S19<=T19,"Detected - Within SLA",IF(AND(R19<>"",R19>IFERROR(INDEX(Settings!$C$5:$C$8,MATCH(G19,Settings!$A$5:$A$8,0)),1E+099)),"Triage Delay","Detected - SLA Breach")))))) -> Detected - Within SLA | W19: =IF(G19="","",IF(L19<>"",1,0)) -> 1 | X19: 46252.61 | Y19: 46252.618 | Z19: 46252.642 | AA19: IR Team | AC19: =IF(AND(G19<>"",L19<>"",X19<>""),(X19-L19)*1440,"") -> 8 | AD19: =IF(AND(G19<>"",X19<>"",Y19<>""),(Y19-X19)*1440,"") -> 12 | AE19: =IF(AND(G19<>"",Y19<>"",Z19<>""),(Z19-Y19)*1440,"") -> 35 | AF19: =IF(AND(G19<>"",L19<>"",Z19<>""),(Z19-L19)*1440,"") -> 55 | AG19: =IF(G19="","",IFERROR(INDEX(Settings!$D$5:$D$8,MATCH(G19,Settings!$A$5:$A$8,0)),"")) -> 240 | AH19: =IF(G19="","",IF(AF19="","No",IF(AF19<=AG19,"Yes","No"))) -> Yes | AI19: =IF(G19="","",IF(L19="","N/A - Not Detected",IF(AND(X19="",Y19="",Z19=""),"No Containment Action",IF(Z19="",IF(Y19<>"","C2 Persisted","Host Isolation Gap"),IF(AF19<=AG19,"Contained - Within SLA","Contained - SLA Breach"))))) -> Contained - Within SLA | AJ19: =IF(G19="","",IF(Z19<>"",1,0)) -> 1 | AK19: operator1 | AL19: 10.0.0.15 | AM19: <command / procedure> | AN19: <tool / C2> | AO19: Y | AP19: Sample observation (placeholder) | AQ19: Not Required | AR19: White Cell | AS19: Complete | AU19: Example row - clear before real use
A20: RT-016 | B20: Q3-2026 Engagement | C20: Command and Control | D20: T1071.001 | E20: Sample event 16 (placeholder) | F20: HOST-16 | G20: High | H20: NDR | I20: 46252.603 | J20: 46252.607 | M20: DE-1016 | N20: Open | P20: =IF(AND(G20<>"",I20<>"",J20<>""),(J20-I20)*1440,"") -> 5 | Q20: =IF(AND(G20<>"",J20<>"",K20<>""),(K20-J20)*1440,"") | R20: =IF(AND(G20<>"",K20<>"",L20<>""),(L20-K20)*1440,"") | S20: =IF(AND(G20<>"",I20<>"",L20<>""),(L20-I20)*1440,"") | T20: =IF(G20="","",IFERROR(INDEX(Settings!$B$5:$B$8,MATCH(G20,Settings!$A$5:$A$8,0)),"")) -> 60 | U20: =IF(G20="","",IF(S20="","No",IF(S20<=T20,"Yes","No"))) -> No | V20: =IF(G20="","",IF(AND(J20="",K20="",L20=""),"Telemetry Blind Spot",IF(AND(K20="",L20=""),"Missed Alert",IF(L20="","Triage Delay",IF(S20<=T20,"Detected - Within SLA",IF(AND(R20<>"",R20>IFERROR(INDEX(Settings!$C$5:$C$8,MATCH(G20,Settings!$A$5:$A$8,0)),1E+099)),"Triage Delay","Detected - SLA Breach")))))) -> Missed Alert | W20: =IF(G20="","",IF(L20<>"",1,0)) -> 0 | AC20: =IF(AND(G20<>"",L20<>"",X20<>""),(X20-L20)*1440,"") | AD20: =IF(AND(G20<>"",X20<>"",Y20<>""),(Y20-X20)*1440,"") | AE20: =IF(AND(G20<>"",Y20<>"",Z20<>""),(Z20-Y20)*1440,"") | AF20: =IF(AND(G20<>"",L20<>"",Z20<>""),(Z20-L20)*1440,"") | AG20: =IF(G20="","",IFERROR(INDEX(Settings!$D$5:$D$8,MATCH(G20,Settings!$A$5:$A$8,0)),"")) -> 240 | AH20: =IF(G20="","",IF(AF20="","No",IF(AF20<=AG20,"Yes","No"))) -> No | AI20: =IF(G20="","",IF(L20="","N/A - Not Detected",IF(AND(X20="",Y20="",Z20=""),"No Containment Action",IF(Z20="",IF(Y20<>"","C2 Persisted","Host Isolation Gap"),IF(AF20<=AG20,"Contained - Within SLA","Contained - SLA Breach"))))) -> N/A - Not Detected | AJ20: =IF(G20="","",IF(Z20<>"",1,0)) -> 0 | AK20: operator1 | AL20: 10.0.0.16 | AM20: <command / procedure> | AN20: <tool / C2> | AO20: Y | AP20: Sample observation (placeholder) | AQ20: Pending | AR20: White Cell | AS20: Pending | AU20: Example row - clear before real use
P21: =IF(AND(G21<>"",I21<>"",J21<>""),(J21-I21)*1440,"") | Q21: =IF(AND(G21<>"",J21<>"",K21<>""),(K21-J21)*1440,"") | R21: =IF(AND(G21<>"",K21<>"",L21<>""),(L21-K21)*1440,"") | S21: =IF(AND(G21<>"",I21<>"",L21<>""),(L21-I21)*1440,"") | T21: =IF(G21="","",IFERROR(INDEX(Settings!$B$5:$B$8,MATCH(G21,Settings!$A$5:$A$8,0)),"")) | U21: =IF(G21="","",IF(S21="","No",IF(S21<=T21,"Yes","No"))) | V21: =IF(G21="","",IF(AND(J21="",K21="",L21=""),"Telemetry Blind Spot",IF(AND(K21="",L21=""),"Missed Alert",IF(L21="","Triage Delay",IF(S21<=T21,"Detected - Within SLA",IF(AND(R21<>"",R21>IFERROR(INDEX(Settings!$C$5:$C$8,MATCH(G21,Settings!$A$5:$A$8,0)),1E+099)),"Triage Delay","Detected - SLA Breach")))))) | W21: =IF(G21="","",IF(L21<>"",1,0)) | AC21: =IF(AND(G21<>"",L21<>"",X21<>""),(X21-L21)*1440,"") | AD21: =IF(AND(G21<>"",X21<>"",Y21<>""),(Y21-X21)*1440,"") | AE21: =IF(AND(G21<>"",Y21<>"",Z21<>""),(Z21-Y21)*1440,"") | AF21: =IF(AND(G21<>"",L21<>"",Z21<>""),(Z21-L21)*1440,"") | AG21: =IF(G21="","",IFERROR(INDEX(Settings!$D$5:$D$8,MATCH(G21,Settings!$A$5:$A$8,0)),"")) | AH21: =IF(G21="","",IF(AF21="","No",IF(AF21<=AG21,"Yes","No"))) | AI21: =IF(G21="","",IF(L21="","N/A - Not Detected",IF(AND(X21="",Y21="",Z21=""),"No Containment Action",IF(Z21="",IF(Y21<>"","C2 Persisted","Host Isolation Gap"),IF(AF21<=AG21,"Contained - Within SLA","Contained - SLA Breach"))))) | AJ21: =IF(G21="","",IF(Z21<>"",1,0))
